Traceback (most recent call last):
  File "/Library/Frameworks/Python.framework/Versions/3.10/lib/python3.10/site-packages/urllib3/connectionpool.py", line 449, in _make_request
    six.raise_from(e, None)
  File "<string>", line 3, in raise_from
  File "/Library/Frameworks/Python.framework/Versions/3.10/lib/python3.10/site-packages/urllib3/connectionpool.py", line 444, in _make_request
    httplib_response = conn.getresponse()
  File "/Library/Frameworks/Python.framework/Versions/3.10/lib/python3.10/http/client.py", line 1374, in getresponse
    response.begin()
  File "/Library/Frameworks/Python.framework/Versions/3.10/lib/python3.10/http/client.py", line 318, in begin
    version, status, reason = self._read_status()
  File "/Library/Frameworks/Python.framework/Versions/3.10/lib/python3.10/http/client.py", line 279, in _read_status
    line = str(self.fp.readline(_MAXLINE + 1), "iso-8859-1")
  File "/Library/Frameworks/Python.framework/Versions/3.10/lib/python3.10/socket.py", line 705, in readinto
    return self._sock.recv_into(b)
  File "/Library/Frameworks/Python.framework/Versions/3.10/lib/python3.10/ssl.py", line 1274, in recv_into
    return self.read(nbytes, buffer)
  File "/Library/Frameworks/Python.framework/Versions/3.10/lib/python3.10/ssl.py", line 1130, in read
    return self._sslobj.read(len, buffer)
TimeoutError: The read operation timed out

During handling of the above exception, another exception occurred:

Traceback (most recent call last):
  File "/Library/Frameworks/Python.framework/Versions/3.10/lib/python3.10/site-packages/requests/adapters.py", line 489, in send
    resp = conn.urlopen(
  File "/Library/Frameworks/Python.framework/Versions/3.10/lib/python3.10/site-packages/urllib3/connectionpool.py", line 787, in urlopen
    retries = retries.increment(
  File "/Library/Frameworks/Python.framework/Versions/3.10/lib/python3.10/site-packages/urllib3/util/retry.py", line 550, in increment
    raise six.reraise(type(error), error, _stacktrace)
  File "/Library/Frameworks/Python.framework/Versions/3.10/lib/python3.10/site-packages/urllib3/packages/six.py", line 770, in reraise
    raise value
  File "/Library/Frameworks/Python.framework/Versions/3.10/lib/python3.10/site-packages/urllib3/connectionpool.py", line 703, in urlopen
    httplib_response = self._make_request(
  File "/Library/Frameworks/Python.framework/Versions/3.10/lib/python3.10/site-packages/urllib3/connectionpool.py", line 451, in _make_request
    self._raise_timeout(err=e, url=url, timeout_value=read_timeout)
  File "/Library/Frameworks/Python.framework/Versions/3.10/lib/python3.10/site-packages/urllib3/connectionpool.py", line 340, in _raise_timeout
    raise ReadTimeoutError(
urllib3.exceptions.ReadTimeoutError: HTTPSConnectionPool(host='stats.nba.com', port=443): Read timed out. (read timeout=30)

During handling of the above exception, another exception occurred:

Traceback (most recent call last):
  File "/Users/harrynguyen/Desktop/courses/summer2023/353/project/01-load-data.py", line 45, in <module>
    if __name__ == '__main__':
  File "/Users/harrynguyen/Desktop/courses/summer2023/353/project/01-load-data.py", line 34, in main
    for _, player in player_data.iterrows():
  File "/Users/harrynguyen/Desktop/courses/summer2023/353/project/01-load-data.py", line 21, in get_player_stats
    def get_player_stats(player: pd.Series) -> pd.DataFrame:
  File "/Library/Frameworks/Python.framework/Versions/3.10/lib/python3.10/site-packages/nba_api/stats/endpoints/playercareerstats.py", line 34, in __init__
    self.get_request()
  File "/Library/Frameworks/Python.framework/Versions/3.10/lib/python3.10/site-packages/nba_api/stats/endpoints/playercareerstats.py", line 37, in get_request
    self.nba_response = NBAStatsHTTP().send_api_request(
  File "/Library/Frameworks/Python.framework/Versions/3.10/lib/python3.10/site-packages/nba_api/library/http.py", line 130, in send_api_request
    response = requests.get(url=base_url, params=parameters, headers=request_headers, proxies=proxies, timeout=timeout)
  File "/Library/Frameworks/Python.framework/Versions/3.10/lib/python3.10/site-packages/requests/api.py", line 73, in get
    return request("get", url, params=params, **kwargs)
  File "/Library/Frameworks/Python.framework/Versions/3.10/lib/python3.10/site-packages/requests/api.py", line 59, in request
    return session.request(method=method, url=url, **kwargs)
  File "/Library/Frameworks/Python.framework/Versions/3.10/lib/python3.10/site-packages/requests/sessions.py", line 587, in request
    resp = self.send(prep, **send_kwargs)
  File "/Library/Frameworks/Python.framework/Versions/3.10/lib/python3.10/site-packages/requests/sessions.py", line 701, in send
    r = adapter.send(request, **kwargs)
  File "/Library/Frameworks/Python.framework/Versions/3.10/lib/python3.10/site-packages/requests/adapters.py", line 578, in send
    raise ReadTimeout(e, request=request)
requests.exceptions.ReadTimeout: HTTPSConnectionPool(host='stats.nba.com', port=443): Read timed out. (read timeout=30)